Traceback (most recent call last):
  File "/home/user/studio/fundacao-alquimista-luxnet/fundacao_unificada/zenith_system/bin/watcher_daemon_zennith.py", line 35, in <module>
    logging.FileHandler(LOG_FILE, encoding='utf-8'),
    ^^^^^^^^^^^^^^^^^^^^^^^^^^^^^^^^^^^^^^^^^^^^^^^
  File "/nix/store/mh6gqjf1w1i6ln1a61psnz0gzdmwrspl-python3-3.11.8/lib/python3.11/logging/__init__.py", line 1181, in __init__
    StreamHandler.__init__(self, self._open())
                                 ^^^^^^^^^^^^
  File "/nix/store/mh6gqjf1w1i6ln1a61psnz0gzdmwrspl-python3-3.11.8/lib/python3.11/logging/__init__.py", line 1213, in _open
    return open_func(self.baseFilename, self.mode,
           ^^^^^^^^^^^^^^^^^^^^^^^^^^^^^^^^^^^^^^^
FileNotFoundError: [Errno 2] No such file or directory: '/home/user/studio/fundacao-alquimista-luxnet/fundacao_unificada/zenith_system/bin/zenith_system/logs/zenith_watcher.log'
